Workbook

Sheet Read Me
B2: Sovereign Compliance & Risk Analysis Dashboard
B3: How this workbook is built, and where it departs from the original blueprint
B5: How to use it
B7: Go to the "Global Overview" or "Country Deep Dive" tab and change the yellow filter cells (they are data-validation dropdowns, not typed text) to update every KPI, table and chart on that tab instantly.
B10: Two deliberate departures from the blueprint (Section 3-4)
B12: 1. Global Risk Heatmap -> Country Risk Ranking table. A native Excel "Filled Map" needs a live Bing Maps geocoding connection that only works inside a real Excel session online, and cannot be produced by an automated script offline. It is replaced with a full 35-country ranking table using the same red-yellow-green 3-colour scale, sorted by Composite Risk Score - the same information, in table form instead of a map.
B14: 2. Excel Slicers -> dropdown filter cells. Native Slicer objects only attach to PivotTables built from a live PivotCache, which openpyxl (the library used to generate this file) cannot create. The filters here are data-validation dropdowns wired to SUMIFS/COUNTIFS/AVERAGEIFS formulas instead, so they drive the same live filtering behaviour - select a value from the dropdown, everything recalculates - just via cell click instead of a floating slicer button.
B17: Data note - Risk Tier column
B19: The Risk_Tier column already present in final_cleaned_dataset.csv (Data!L) uses only two labels ("Low Risk" / "Medium Risk") - no row in the source file is tagged "High Risk", even though Composite Risk Score reaches 72.4 (Congo, Dem. Rep., 2017 and 2024), well above the blueprint's own >65 threshold. This means the source file's tiering does not follow the formula defined in Section 2.4 of the blueprint (IF Score > 65 -> "High Risk", 40-65 -> "Medium Risk", < 40 -> "Low Risk"). Rather than silently reuse the source labels, this workbook adds a new formula-driven column, Risk_Tier_Calc (Data!N), that applies the blueprint's exact formula, and every tier-based KPI, chart and conditional format in this workbook (Risk Tier Breakdown donut, High Risk Countries KPI, ranking table colours) uses that column, not the original one. The original Risk_Tier column is left untouched in place for reference/comparison.
B22: Workbook map
B24: Global Overview / Country Deep Dive - the two dashboard tabs. Data - the 420-row cleaned dataset as an Excel Table, plus the two computed columns above. CountryMeta - static Country -> Region/Income lookup used by the dropdowns. Lookups, Calc_T1, Calc_T2 - hidden helper sheets holding the filter option lists and the per-country formulas that power the KPIs and charts; right-click any sheet tab and choose Unhide to inspect them.

Sheet Global Overview
B1: Sovereign Compliance & Risk Analysis Dashboard
B2: Global Overview | 35 Countries across 7 Regions | 2013-2024 | Source: World Bank WGI & WDI
B4: FILTERS
B5: Region: | C5: All Regions | E5: Income Group: | F5: All Income Groups | H5: Year: | I5: 2024
B7: TOTAL COUNTRIES ANALYZED | E7: AVERAGE GLOBAL RISK SCORE | H7: HIGH RISK COUNTRIES (>65) | K7: SAFEST COUNTRY (LOWEST RISK)
B8: =COUNTIF(Calc_T1!$D$2:$D$36,TRUE()) -> 35 | E8: =ROUND(AVERAGE(Calc_T1!$K$2:$K$36),1) -> 45.1 | H8: =COUNTIFS(Calc_T1!$D$2:$D$36,TRUE(),Calc_T1!$J$2:$J$36,"High Risk") -> 3 | K8: =IFERROR(INDEX(Calc_T1!$A$2:$A$36,MATCH(MIN(Calc_T1!$K$2:$K$36),Calc_T1!$K$2:$K$36,0)),"n/a") -> Australia
B10: RISKIEST COUNTRY (HIGHEST RISK) | E10: MOST IMPROVED (2013 -> 2024, biggest score decrease) | I10: MOST DETERIORATED (2013 -> 2024, biggest score increase)
B11: =IFERROR(INDEX(Calc_T1!$A$2:$A$36,MATCH(MAX(Calc_T1!$K$2:$K$36),Calc_T1!$K$2:$K$36,0)),"n/a") -> Congo, Dem. Rep. | E11: =IFERROR(INDEX(Calc_T1!$A$2:$A$36,MATCH(MIN(Calc_T1!$I$2:$I$36),Calc_T1!$I$2:$I$36,0))&" ("&TEXT(MIN(Calc_T1!$I$2:$I$36),"+0.0;-0.0")&")","n/a") -> Saudi Arabia (-10.8) | I11: =IFERROR(INDEX(Calc_T1!$A$2:$A$36,MATCH(MAX(Calc_T1!$I$2:$I$36),Calc_T1!$I$2:$I$36,0))&" ("&TEXT(MAX(Calc_T1!$I$2:$I$36),"+0.0;-0.0")&")","n/a") -> Turkiye (+9.2)
B13: COUNTRY RISK RANKING (sorted by Composite Risk Score, selected year) | I13: TOP 10 RISKIEST COUNTRIES (selected filters/year)
B14: Note: Excel Filled Maps require a live Bing Maps connection that cannot be generated offline, so this color-scaled ranking table stands in as the geographic heatmap — same information, table form.
B16: Rank | C16: Country | D16: Region | E16: Composite Risk Score | F16: Risk Tier | I16: Rank | J16: Country | K16: Risk Score
B17: 1 | C17: =IFERROR(INDEX(Calc_T1!$A$2:$A$36,MATCH($B17,Calc_T1!$M$2:$M$36,0)),"") -> Congo, Dem. Rep. | D17: =IFERROR(INDEX(Calc_T1!$B$2:$B$36,MATCH($B17,Calc_T1!$M$2:$M$36,0)),"") -> Sub-Saharan Africa | E17: =IFERROR(INDEX(Calc_T1!$K$2:$K$36,MATCH($B17,Calc_T1!$M$2:$M$36,0)),"") -> 72.39 | F17: =IFERROR(INDEX(Calc_T1!$J$2:$J$36,MATCH($B17,Calc_T1!$M$2:$M$36,0)),"") -> High Risk | I17: 1 | J17: =IFERROR(INDEX(Calc_T1!$A$2:$A$36,MATCH($I17,Calc_T1!$M$2:$M$36,0)),"") -> Congo, Dem. Rep. | K17: =IFERROR(INDEX(Calc_T1!$K$2:$K$36,MATCH($I17,Calc_T1!$M$2:$M$36,0)),"") -> 72.39
B18: 2 | C18: =IFERROR(INDEX(Calc_T1!$A$2:$A$36,MATCH($B18,Calc_T1!$M$2:$M$36,0)),"") -> Iran, Islamic Rep. | D18: =IFERROR(INDEX(Calc_T1!$B$2:$B$36,MATCH($B18,Calc_T1!$M$2:$M$36,0)),"") -> Middle East & North Africa | E18: =IFERROR(INDEX(Calc_T1!$K$2:$K$36,MATCH($B18,Calc_T1!$M$2:$M$36,0)),"") -> 67.44 | F18: =IFERROR(INDEX(Calc_T1!$J$2:$J$36,MATCH($B18,Calc_T1!$M$2:$M$36,0)),"") -> High Risk | I18: 2 | J18: =IFERROR(INDEX(Calc_T1!$A$2:$A$36,MATCH($I18,Calc_T1!$M$2:$M$36,0)),"") -> Iran, Islamic Rep. | K18: =IFERROR(INDEX(Calc_T1!$K$2:$K$36,MATCH($I18,Calc_T1!$M$2:$M$36,0)),"") -> 67.44
B19: 3 | C19: =IFERROR(INDEX(Calc_T1!$A$2:$A$36,MATCH($B19,Calc_T1!$M$2:$M$36,0)),"") -> Pakistan | D19: =IFERROR(INDEX(Calc_T1!$B$2:$B$36,MATCH($B19,Calc_T1!$M$2:$M$36,0)),"") -> South Asia | E19: =IFERROR(INDEX(Calc_T1!$K$2:$K$36,MATCH($B19,Calc_T1!$M$2:$M$36,0)),"") -> 65.31 | F19: =IFERROR(INDEX(Calc_T1!$J$2:$J$36,MATCH($B19,Calc_T1!$M$2:$M$36,0)),"") -> High Risk | I19: 3 | J19: =IFERROR(INDEX(Calc_T1!$A$2:$A$36,MATCH($I19,Calc_T1!$M$2:$M$36,0)),"") -> Pakistan | K19: =IFERROR(INDEX(Calc_T1!$K$2:$K$36,MATCH($I19,Calc_T1!$M$2:$M$36,0)),"") -> 65.31
B20: 4 | C20: =IFERROR(INDEX(Calc_T1!$A$2:$A$36,MATCH($B20,Calc_T1!$M$2:$M$36,0)),"") -> Nigeria | D20: =IFERROR(INDEX(Calc_T1!$B$2:$B$36,MATCH($B20,Calc_T1!$M$2:$M$36,0)),"") -> Sub-Saharan Africa | E20: =IFERROR(INDEX(Calc_T1!$K$2:$K$36,MATCH($B20,Calc_T1!$M$2:$M$36,0)),"") -> 64.63 | F20: =IFERROR(INDEX(Calc_T1!$J$2:$J$36,MATCH($B20,Calc_T1!$M$2:$M$36,0)),"") -> Medium Risk | I20: 4 | J20: =IFERROR(INDEX(Calc_T1!$A$2:$A$36,MATCH($I20,Calc_T1!$M$2:$M$36,0)),"") -> Nigeria | K20: =IFERROR(INDEX(Calc_T1!$K$2:$K$36,MATCH($I20,Calc_T1!$M$2:$M$36,0)),"") -> 64.63
B21: 5 | C21: =IFERROR(INDEX(Calc_T1!$A$2:$A$36,MATCH($B21,Calc_T1!$M$2:$M$36,0)),"") -> Bangladesh | D21: =IFERROR(INDEX(Calc_T1!$B$2:$B$36,MATCH($B21,Calc_T1!$M$2:$M$36,0)),"") -> South Asia | E21: =IFERROR(INDEX(Calc_T1!$K$2:$K$36,MATCH($B21,Calc_T1!$M$2:$M$36,0)),"") -> 63.31 | F21: =IFERROR(INDEX(Calc_T1!$J$2:$J$36,MATCH($B21,Calc_T1!$M$2:$M$36,0)),"") -> Medium Risk | I21: 5 | J21: =IFERROR(INDEX(Calc_T1!$A$2:$A$36,MATCH($I21,Calc_T1!$M$2:$M$36,0)),"") -> Bangladesh | K21: =IFERROR(INDEX(Calc_T1!$K$2:$K$36,MATCH($I21,Calc_T1!$M$2:$M$36,0)),"") -> 63.31
B22: 6 | C22: =IFERROR(INDEX(Calc_T1!$A$2:$A$36,MATCH($B22,Calc_T1!$M$2:$M$36,0)),"") -> Ethiopia | D22: =IFERROR(INDEX(Calc_T1!$B$2:$B$36,MATCH($B22,Calc_T1!$M$2:$M$36,0)),"") -> Sub-Saharan Africa | E22: =IFERROR(INDEX(Calc_T1!$K$2:$K$36,MATCH($B22,Calc_T1!$M$2:$M$36,0)),"") -> 61.67 | F22: =IFERROR(INDEX(Calc_T1!$J$2:$J$36,MATCH($B22,Calc_T1!$M$2:$M$36,0)),"") -> Medium Risk | I22: 6 | J22: =IFERROR(INDEX(Calc_T1!$A$2:$A$36,MATCH($I22,Calc_T1!$M$2:$M$36,0)),"") -> Ethiopia | K22: =IFERROR(INDEX(Calc_T1!$K$2:$K$36,MATCH($I22,Calc_T1!$M$2:$M$36,0)),"") -> 61.67
B23: 7 | C23: =IFERROR(INDEX(Calc_T1!$A$2:$A$36,MATCH($B23,Calc_T1!$M$2:$M$36,0)),"") -> Russian Federation | D23: =IFERROR(INDEX(Calc_T1!$B$2:$B$36,MATCH($B23,Calc_T1!$M$2:$M$36,0)),"") -> Europe & Central Asia | E23: =IFERROR(INDEX(Calc_T1!$K$2:$K$36,MATCH($B23,Calc_T1!$M$2:$M$36,0)),"") -> 61.16 | F23: =IFERROR(INDEX(Calc_T1!$J$2:$J$36,MATCH($B23,Calc_T1!$M$2:$M$36,0)),"") -> Medium Risk | I23: 7 | J23: =IFERROR(INDEX(Calc_T1!$A$2:$A$36,MATCH($I23,Calc_T1!$M$2:$M$36,0)),"") -> Russian Federation | K23: =IFERROR(INDEX(Calc_T1!$K$2:$K$36,MATCH($I23,Calc_T1!$M$2:$M$36,0)),"") -> 61.16
B24: 8 | C24: =IFERROR(INDEX(Calc_T1!$A$2:$A$36,MATCH($B24,Calc_T1!$M$2:$M$36,0)),"") -> Egypt, Arab Rep. | D24: =IFERROR(INDEX(Calc_T1!$B$2:$B$36,MATCH($B24,Calc_T1!$M$2:$M$36,0)),"") -> Middle East & North Africa | E24: =IFERROR(INDEX(Calc_T1!$K$2:$K$36,MATCH($B24,Calc_T1!$M$2:$M$36,0)),"") -> 57.17 | F24: =IFERROR(INDEX(Calc_T1!$J$2:$J$36,MATCH($B24,Calc_T1!$M$2:$M$36,0)),"") -> Medium Risk | I24: 8 | J24: =IFERROR(INDEX(Calc_T1!$A$2:$A$36,MATCH($I24,Calc_T1!$M$2:$M$36,0)),"") -> Egypt, Arab Rep. | K24: =IFERROR(INDEX(Calc_T1!$K$2:$K$36,MATCH($I24,Calc_T1!$M$2:$M$36,0)),"") -> 57.17
B25: 9 | C25: =IFERROR(INDEX(Calc_T1!$A$2:$A$36,MATCH($B25,Calc_T1!$M$2:$M$36,0)),"") -> Mexico | D25: =IFERROR(INDEX(Calc_T1!$B$2:$B$36,MATCH($B25,Calc_T1!$M$2:$M$36,0)),"") -> Latin America & Caribbean | E25: =IFERROR(INDEX(Calc_T1!$K$2:$K$36,MATCH($B25,Calc_T1!$M$2:$M$36,0)),"") -> 57.16 | F25: =IFERROR(INDEX(Calc_T1!$J$2:$J$36,MATCH($B25,Calc_T1!$M$2:$M$36,0)),"") -> Medium Risk | I25: 9 | J25: =IFERROR(INDEX(Calc_T1!$A$2:$A$36,MATCH($I25,Calc_T1!$M$2:$M$36,0)),"") -> Mexico | K25: =IFERROR(INDEX(Calc_T1!$K$2:$K$36,MATCH($I25,Calc_T1!$M$2:$M$36,0)),"") -> 57.16
B26: 10 | C26: =IFERROR(INDEX(Calc_T1!$A$2:$A$36,MATCH($B26,Calc_T1!$M$2:$M$36,0)),"") -> Kenya | D26: =IFERROR(INDEX(Calc_T1!$B$2:$B$36,MATCH($B26,Calc_T1!$M$2:$M$36,0)),"") -> Sub-Saharan Africa | E26: =IFERROR(INDEX(Calc_T1!$K$2:$K$36,MATCH($B26,Calc_T1!$M$2:$M$36,0)),"") -> 56.77 | F26: =IFERROR(INDEX(Calc_T1!$J$2:$J$36,MATCH($B26,Calc_T1!$M$2:$M$36,0)),"") -> Medium Risk | I26: 10 | J26: =IFERROR(INDEX(Calc_T1!$A$2:$A$36,MATCH($I26,Calc_T1!$M$2:$M$36,0)),"") -> Kenya | K26: =IFERROR(INDEX(Calc_T1!$K$2:$K$36,MATCH($I26,Calc_T1!$M$2:$M$36,0)),"") -> 56.77
B27: 11 | C27: =IFERROR(INDEX(Calc_T1!$A$2:$A$36,MATCH($B27,Calc_T1!$M$2:$M$36,0)),"") -> Turkiye | D27: =IFERROR(INDEX(Calc_T1!$B$2:$B$36,MATCH($B27,Calc_T1!$M$2:$M$36,0)),"") -> Europe & Central Asia | E27: =IFERROR(INDEX(Calc_T1!$K$2:$K$36,MATCH($B27,Calc_T1!$M$2:$M$36,0)),"") -> 55.06 | F27: =IFERROR(INDEX(Calc_T1!$J$2:$J$36,MATCH($B27,Calc_T1!$M$2:$M$36,0)),"") -> Medium Risk
B28: 12 | C28: =IFERROR(INDEX(Calc_T1!$A$2:$A$36,MATCH($B28,Calc_T1!$M$2:$M$36,0)),"") -> Philippines | D28: =IFERROR(INDEX(Calc_T1!$B$2:$B$36,MATCH($B28,Calc_T1!$M$2:$M$36,0)),"") -> East Asia & Pacific | E28: =IFERROR(INDEX(Calc_T1!$K$2:$K$36,MATCH($B28,Calc_T1!$M$2:$M$36,0)),"") -> 51.99 | F28: =IFERROR(INDEX(Calc_T1!$J$2:$J$36,MATCH($B28,Calc_T1!$M$2:$M$36,0)),"") -> Medium Risk | I28: RISK TIER BREAKDOWN (selected filters/year)
B29: 13 | C29: =IFERROR(INDEX(Calc_T1!$A$2:$A$36,MATCH($B29,Calc_T1!$M$2:$M$36,0)),"") -> Colombia | D29: =IFERROR(INDEX(Calc_T1!$B$2:$B$36,MATCH($B29,Calc_T1!$M$2:$M$36,0)),"") -> Latin America & Caribbean | E29: =IFERROR(INDEX(Calc_T1!$K$2:$K$36,MATCH($B29,Calc_T1!$M$2:$M$36,0)),"") -> 51.59 | F29: =IFERROR(INDEX(Calc_T1!$J$2:$J$36,MATCH($B29,Calc_T1!$M$2:$M$36,0)),"") -> Medium Risk | I29: Risk Tier | J29: Count
B30: 14 | C30: =IFERROR(INDEX(Calc_T1!$A$2:$A$36,MATCH($B30,Calc_T1!$M$2:$M$36,0)),"") -> Brazil | D30: =IFERROR(INDEX(Calc_T1!$B$2:$B$36,MATCH($B30,Calc_T1!$M$2:$M$36,0)),"") -> Latin America & Caribbean | E30: =IFERROR(INDEX(Calc_T1!$K$2:$K$36,MATCH($B30,Calc_T1!$M$2:$M$36,0)),"") -> 50.98 | F30: =IFERROR(INDEX(Calc_T1!$J$2:$J$36,MATCH($B30,Calc_T1!$M$2:$M$36,0)),"") -> Medium Risk | I30: High Risk | J30: =COUNTIFS(Calc_T1!$D$2:$D$36,TRUE(),Calc_T1!$J$2:$J$36,"High Risk") -> 3
B31: 15 | C31: =IFERROR(INDEX(Calc_T1!$A$2:$A$36,MATCH($B31,Calc_T1!$M$2:$M$36,0)),"") -> Indonesia | D31: =IFERROR(INDEX(Calc_T1!$B$2:$B$36,MATCH($B31,Calc_T1!$M$2:$M$36,0)),"") -> East Asia & Pacific | E31: =IFERROR(INDEX(Calc_T1!$K$2:$K$36,MATCH($B31,Calc_T1!$M$2:$M$36,0)),"") -> 49.36 | F31: =IFERROR(INDEX(Calc_T1!$J$2:$J$36,MATCH($B31,Calc_T1!$M$2:$M$36,0)),"") -> Medium Risk | I31: Medium Risk | J31: =COUNTIFS(Calc_T1!$D$2:$D$36,TRUE(),Calc_T1!$J$2:$J$36,"Medium Risk") -> 19
B32: 16 | C32: =IFERROR(INDEX(Calc_T1!$A$2:$A$36,MATCH($B32,Calc_T1!$M$2:$M$36,0)),"") -> Sri Lanka | D32: =IFERROR(INDEX(Calc_T1!$B$2:$B$36,MATCH($B32,Calc_T1!$M$2:$M$36,0)),"") -> South Asia | E32: =IFERROR(INDEX(Calc_T1!$K$2:$K$36,MATCH($B32,Calc_T1!$M$2:$M$36,0)),"") -> 49.34 | F32: =IFERROR(INDEX(Calc_T1!$J$2:$J$36,MATCH($B32,Calc_T1!$M$2:$M$36,0)),"") -> Medium Risk | I32: Low Risk | J32: =COUNTIFS(Calc_T1!$D$2:$D$36,TRUE(),Calc_T1!$J$2:$J$36,"Low Risk") -> 13
B33: 17 | C33: =IFERROR(INDEX(Calc_T1!$A$2:$A$36,MATCH($B33,Calc_T1!$M$2:$M$36,0)),"") -> India | D33: =IFERROR(INDEX(Calc_T1!$B$2:$B$36,MATCH($B33,Calc_T1!$M$2:$M$36,0)),"") -> South Asia | E33: =IFERROR(INDEX(Calc_T1!$K$2:$K$36,MATCH($B33,Calc_T1!$M$2:$M$36,0)),"") -> 49 | F33: =IFERROR(INDEX(Calc_T1!$J$2:$J$36,MATCH($B33,Calc_T1!$M$2:$M$36,0)),"") -> Medium Risk
B34: 18 | C34: =IFERROR(INDEX(Calc_T1!$A$2:$A$36,MATCH($B34,Calc_T1!$M$2:$M$36,0)),"") -> Argentina | D34: =IFERROR(INDEX(Calc_T1!$B$2:$B$36,MATCH($B34,Calc_T1!$M$2:$M$36,0)),"") -> Latin America & Caribbean | E34: =IFERROR(INDEX(Calc_T1!$K$2:$K$36,MATCH($B34,Calc_T1!$M$2:$M$36,0)),"") -> 47.99 | F34: =IFERROR(INDEX(Calc_T1!$J$2:$J$36,MATCH($B34,Calc_T1!$M$2:$M$36,0)),"") -> Medium Risk
B35: 19 | C35: =IFERROR(INDEX(Calc_T1!$A$2:$A$36,MATCH($B35,Calc_T1!$M$2:$M$36,0)),"") -> South Africa | D35: =IFERROR(INDEX(Calc_T1!$B$2:$B$36,MATCH($B35,Calc_T1!$M$2:$M$36,0)),"") -> Sub-Saharan Africa | E35: =IFERROR(INDEX(Calc_T1!$K$2:$K$36,MATCH($B35,Calc_T1!$M$2:$M$36,0)),"") -> 47.37 | F35: =IFERROR(INDEX(Calc_T1!$J$2:$J$36,MATCH($B35,Calc_T1!$M$2:$M$36,0)),"") -> Medium Risk
B36: 20 | C36: =IFERROR(INDEX(Calc_T1!$A$2:$A$36,MATCH($B36,Calc_T1!$M$2:$M$36,0)),"") -> Kazakhstan | D36: =IFERROR(INDEX(Calc_T1!$B$2:$B$36,MATCH($B36,Calc_T1!$M$2:$M$36,0)),"") -> Europe & Central Asia | E36: =IFERROR(INDEX(Calc_T1!$K$2:$K$36,MATCH($B36,Calc_T1!$M$2:$M$36,0)),"") -> 46.61 | F36: =IFERROR(INDEX(Calc_T1!$J$2:$J$36,MATCH($B36,Calc_T1!$M$2:$M$36,0)),"") -> Medium Risk
B37: 21 | C37: =IFERROR(INDEX(Calc_T1!$A$2:$A$36,MATCH($B37,Calc_T1!$M$2:$M$36,0)),"") -> China | D37: =IFERROR(INDEX(Calc_T1!$B$2:$B$36,MATCH($B37,Calc_T1!$M$2:$M$36,0)),"") -> East Asia & Pacific | E37: =IFERROR(INDEX(Calc_T1!$K$2:$K$36,MATCH($B37,Calc_T1!$M$2:$M$36,0)),"") -> 46.59 | F37: =IFERROR(INDEX(Calc_T1!$J$2:$J$36,MATCH($B37,Calc_T1!$M$2:$M$36,0)),"") -> Medium Risk
B38: 22 | C38: =IFERROR(INDEX(Calc_T1!$A$2:$A$36,MATCH($B38,Calc_T1!$M$2:$M$36,0)),"") -> Georgia | D38: =IFERROR(INDEX(Calc_T1!$B$2:$B$36,MATCH($B38,Calc_T1!$M$2:$M$36,0)),"") -> Europe & Central Asia | E38: =IFERROR(INDEX(Calc_T1!$K$2:$K$36,MATCH($B38,Calc_T1!$M$2:$M$36,0)),"") -> 41.09 | F38: =IFERROR(INDEX(Calc_T1!$J$2:$J$36,MATCH($B38,Calc_T1!$M$2:$M$36,0)),"") -> Medium Risk
B39: 23 | C39: =IFERROR(INDEX(Calc_T1!$A$2:$A$36,MATCH($B39,Calc_T1!$M$2:$M$36,0)),"") -> Greece | D39: =IFERROR(INDEX(Calc_T1!$B$2:$B$36,MATCH($B39,Calc_T1!$M$2:$M$36,0)),"") -> Europe & Central Asia | E39: =IFERROR(INDEX(Calc_T1!$K$2:$K$36,MATCH($B39,Calc_T1!$M$2:$M$36,0)),"") -> 38.32 | F39: =IFERROR(INDEX(Calc_T1!$J$2:$J$36,MATCH($B39,Calc_T1!$M$2:$M$36,0)),"") -> Low Risk
B40: 24 | C40: =IFERROR(INDEX(Calc_T1!$A$2:$A$36,MATCH($B40,Calc_T1!$M$2:$M$36,0)),"") -> Saudi Arabia | D40: =IFERROR(INDEX(Calc_T1!$B$2:$B$36,MATCH($B40,Calc_T1!$M$2:$M$36,0)),"") -> Middle East & North Africa | E40: =IFERROR(INDEX(Calc_T1!$K$2:$K$36,MATCH($B40,Calc_T1!$M$2:$M$36,0)),"") -> 36.3 | F40: =IFERROR(INDEX(Calc_T1!$J$2:$J$36,MATCH($B40,Calc_T1!$M$2:$M$36,0)),"") -> Low Risk
B41: 25 | C41: =IFERROR(INDEX(Calc_T1!$A$2:$A$36,MATCH($B41,Calc_T1!$M$2:$M$36,0)),"") -> Italy | D41: =IFERROR(INDEX(Calc_T1!$B$2:$B$36,MATCH($B41,Calc_T1!$M$2:$M$36,0)),"") -> Europe & Central Asia | E41: =IFERROR(INDEX(Calc_T1!$K$2:$K$36,MATCH($B41,Calc_T1!$M$2:$M$36,0)),"") -> 34.3 | F41: =IFERROR(INDEX(Calc_T1!$J$2:$J$36,MATCH($B41,Calc_T1!$M$2:$M$36,0)),"") -> Low Risk
B42: 26 | C42: =IFERROR(INDEX(Calc_T1!$A$2:$A$36,MATCH($B42,Calc_T1!$M$2:$M$36,0)),"") -> Poland | D42: =IFERROR(INDEX(Calc_T1!$B$2:$B$36,MATCH($B42,Calc_T1!$M$2:$M$36,0)),"") -> Europe & Central Asia | E42: =IFERROR(INDEX(Calc_T1!$K$2:$K$36,MATCH($B42,Calc_T1!$M$2:$M$36,0)),"") -> 32.27 | F42: =IFERROR(INDEX(Calc_T1!$J$2:$J$36,MATCH($B42,Calc_T1!$M$2:$M$36,0)),"") -> Low Risk
B43: 27 | C43: =IFERROR(INDEX(Calc_T1!$A$2:$A$36,MATCH($B43,Calc_T1!$M$2:$M$36,0)),"") -> Chile | D43: =IFERROR(INDEX(Calc_T1!$B$2:$B$36,MATCH($B43,Calc_T1!$M$2:$M$36,0)),"") -> Latin America & Caribbean | E43: =IFERROR(INDEX(Calc_T1!$K$2:$K$36,MATCH($B43,Calc_T1!$M$2:$M$36,0)),"") -> 31.44 | F43: =IFERROR(INDEX(Calc_T1!$J$2:$J$36,MATCH($B43,Calc_T1!$M$2:$M$36,0)),"") -> Low Risk
B44: 28 | C44: =IFERROR(INDEX(Calc_T1!$A$2:$A$36,MATCH($B44,Calc_T1!$M$2:$M$36,0)),"") -> France | D44: =IFERROR(INDEX(Calc_T1!$B$2:$B$36,MATCH($B44,Calc_T1!$M$2:$M$36,0)),"") -> Europe & Central Asia | E44: =IFERROR(INDEX(Calc_T1!$K$2:$K$36,MATCH($B44,Calc_T1!$M$2:$M$36,0)),"") -> 29.74 | F44: =IFERROR(INDEX(Calc_T1!$J$2:$J$36,MATCH($B44,Calc_T1!$M$2:$M$36,0)),"") -> Low Risk
... B51: 35 | C51: =IFERROR(INDEX(Calc_T1!$A$2:$A$36,MATCH($B51,Calc_T1!$M$2:$M$36,0)),"") -> Australia | D51: =IFERROR(INDEX(Calc_T1!$B$2:$B$36,MATCH($B51,Calc_T1!$M$2:$M$36,0)),"") -> East Asia & Pacific | E51: =IFERROR(INDEX(Calc_T1!$K$2:$K$36,MATCH($B51,Calc_T1!$M$2:$M$36,0)),"") -> 17.73 | F51: =IFERROR(INDEX(Calc_T1!$J$2:$J$36,MATCH($B51,Calc_T1!$M$2:$M$36,0)),"") -> Low Risk
...

Sheet Country Deep Dive
B1: Sovereign Compliance & Risk Analysis Dashboard
B2: Country Deep Dive | Select a country to explore its governance profile in detail
B4: FILTERS
B5: Country: | C5: India | E5: Start Year: | F5: 2013 | H5: End Year: | I5: 2024
B7: SELECTED COUNTRY | E7: RISK SCORE (END YEAR) | H7: RISK TIER (END YEAR) | K7: SCORE CHANGE (START -> END YEAR)
B8: =T2_Country -> India | E8: =ROUND(SUMIFS(Data!$K:$K,Data!$A:$A,T2_Country,Data!$C:$C,T2_EndYear),2) -> 49 | H8: =IF(SUMIFS(Data!$K:$K,Data!$A:$A,T2_Country,Data!$C:$C,T2_EndYear)>65,"High Risk",IF(SUMIFS(Data!$K:$K,Data!$A:$A,T2_Country,Data!$C:$C,T2_EndYear)>=40,"Medium Risk","Low Risk")) -> Medium Risk | K8: =ROUND(SUMIFS(Data!$K:$K,Data!$A:$A,T2_Country,Data!$C:$C,T2_EndYear)-SUMIFS(Data!$K:$K,Data!$A:$A,T2_Country,Data!$C:$C,T2_StartYear),2) -> -3.96
B12: GOVERNANCE BREAKDOWN (End Year) | J12: COUNTRY RISK TREND (2013-2024)
B13: Pillar | C13: Score | J13: Year | K13: Risk Score
B14: Control of Corruption | C14: =SUMIFS(Data!$F:$F,Data!$A:$A,T2_Country,Data!$C:$C,T2_EndYear) -> 41.88 | J14: 2013 | K14: =ROUND(SUMIFS(Data!$K:$K,Data!$A:$A,T2_Country,Data!$C:$C,$J14),2) -> 52.96
B15: Rule of Law | C15: =SUMIFS(Data!$G:$G,Data!$A:$A,T2_Country,Data!$C:$C,T2_EndYear) -> 56.29 | J15: 2014 | K15: =ROUND(SUMIFS(Data!$K:$K,Data!$A:$A,T2_Country,Data!$C:$C,$J15),2) -> 51.41
B16: Regulatory Quality | C16: =SUMIFS(Data!$H:$H,Data!$A:$A,T2_Country,Data!$C:$C,T2_EndYear) -> 53.35 | J16: 2015 | K16: =ROUND(SUMIFS(Data!$K:$K,Data!$A:$A,T2_Country,Data!$C:$C,$J16),2) -> 50.5
B17: Political Stability | C17: =SUMIFS(Data!$I:$I,Data!$A:$A,T2_Country,Data!$C:$C,T2_EndYear) -> 52.47 | J17: 2016 | K17: =ROUND(SUMIFS(Data!$K:$K,Data!$A:$A,T2_Country,Data!$C:$C,$J17),2) -> 49.55
J18: 2017 | K18: =ROUND(SUMIFS(Data!$K:$K,Data!$A:$A,T2_Country,Data!$C:$C,$J18),2) -> 48.21
J19: 2018 | K19: =ROUND(SUMIFS(Data!$K:$K,Data!$A:$A,T2_Country,Data!$C:$C,$J19),2) -> 48.08
J20: 2019 | K20: =ROUND(SUMIFS(Data!$K:$K,Data!$A:$A,T2_Country,Data!$C:$C,$J20),2) -> 47.71
J21: 2020 | K21: =ROUND(SUMIFS(Data!$K:$K,Data!$A:$A,T2_Country,Data!$C:$C,$J21),2) -> 49
J22: 2021 | K22: =ROUND(SUMIFS(Data!$K:$K,Data!$A:$A,T2_Country,Data!$C:$C,$J22),2) -> 49.16
J23: 2022 | K23: =ROUND(SUMIFS(Data!$K:$K,Data!$A:$A,T2_Country,Data!$C:$C,$J23),2) -> 49.12
J24: 2023 | K24: =ROUND(SUMIFS(Data!$K:$K,Data!$A:$A,T2_Country,Data!$C:$C,$J24),2) -> 49.76
J25: 2024 | K25: =ROUND(SUMIFS(Data!$K:$K,Data!$A:$A,T2_Country,Data!$C:$C,$J25),2) -> 49
B29: REGIONAL PEER COMPARISON (End Year, same region as selected country) | J29: PILLAR SCORES OVER TIME (2013-2024)
B30: Rank | C30: Country | D30: Risk Score | J30: Year | K30: Corruption | L30: Rule of Law | M30: Reg. Quality | N30: Pol. Stability
B31: 1 | C31: =IFERROR(INDEX(Calc_T2!$A$2:$A$36,MATCH($B31,Calc_T2!$E$2:$E$36,0)),"") -> Pakistan | D31: =IFERROR(INDEX(Calc_T2!$C$2:$C$36,MATCH($B31,Calc_T2!$E$2:$E$36,0)),"") -> 65.31 | J31: 2013 | K31: =ROUND(SUMIFS(Data!$F:$F,Data!$A:$A,T2_Country,Data!$C:$C,$J31),2) -> 38.33 | L31: =ROUND(SUMIFS(Data!$G:$G,Data!$A:$A,T2_Country,Data!$C:$C,$J31),2) -> 54.97 | M31: =ROUND(SUMIFS(Data!$H:$H,Data!$A:$A,T2_Country,Data!$C:$C,$J31),2) -> 48.99 | N31: =ROUND(SUMIFS(Data!$I:$I,Data!$A:$A,T2_Country,Data!$C:$C,$J31),2) -> 45.89
B32: 2 | C32: =IFERROR(INDEX(Calc_T2!$A$2:$A$36,MATCH($B32,Calc_T2!$E$2:$E$36,0)),"") -> Bangladesh | D32: =IFERROR(INDEX(Calc_T2!$C$2:$C$36,MATCH($B32,Calc_T2!$E$2:$E$36,0)),"") -> 63.31 | J32: 2014 | K32: =ROUND(SUMIFS(Data!$F:$F,Data!$A:$A,T2_Country,Data!$C:$C,$J32),2) -> 39.48 | L32: =ROUND(SUMIFS(Data!$G:$G,Data!$A:$A,T2_Country,Data!$C:$C,$J32),2) -> 54.11 | M32: =ROUND(SUMIFS(Data!$H:$H,Data!$A:$A,T2_Country,Data!$C:$C,$J32),2) -> 48.86 | N32: =ROUND(SUMIFS(Data!$I:$I,Data!$A:$A,T2_Country,Data!$C:$C,$J32),2) -> 51.93
B33: 3 | C33: =IFERROR(INDEX(Calc_T2!$A$2:$A$36,MATCH($B33,Calc_T2!$E$2:$E$36,0)),"") -> Sri Lanka | D33: =IFERROR(INDEX(Calc_T2!$C$2:$C$36,MATCH($B33,Calc_T2!$E$2:$E$36,0)),"") -> 49.34 | J33: 2015 | K33: =ROUND(SUMIFS(Data!$F:$F,Data!$A:$A,T2_Country,Data!$C:$C,$J33),2) -> 40.87 | L33: =ROUND(SUMIFS(Data!$G:$G,Data!$A:$A,T2_Country,Data!$C:$C,$J33),2) -> 54.6 | M33: =ROUND(SUMIFS(Data!$H:$H,Data!$A:$A,T2_Country,Data!$C:$C,$J33),2) -> 49.65 | N33: =ROUND(SUMIFS(Data!$I:$I,Data!$A:$A,T2_Country,Data!$C:$C,$J33),2) -> 52.88
B34: 4 | C34: =IFERROR(INDEX(Calc_T2!$A$2:$A$36,MATCH($B34,Calc_T2!$E$2:$E$36,0)),"") -> India | D34: =IFERROR(INDEX(Calc_T2!$C$2:$C$36,MATCH($B34,Calc_T2!$E$2:$E$36,0)),"") -> 49 | J34: 2016 | K34: =ROUND(SUMIFS(Data!$F:$F,Data!$A:$A,T2_Country,Data!$C:$C,$J34),2) -> 42.08 | L34: =ROUND(SUMIFS(Data!$G:$G,Data!$A:$A,T2_Country,Data!$C:$C,$J34),2) -> 55.55 | M34: =ROUND(SUMIFS(Data!$H:$H,Data!$A:$A,T2_Country,Data!$C:$C,$J34),2) -> 50.86 | N34: =ROUND(SUMIFS(Data!$I:$I,Data!$A:$A,T2_Country,Data!$C:$C,$J34),2) -> 53.32
B35: 5 | C35: =IFERROR(INDEX(Calc_T2!$A$2:$A$36,MATCH($B35,Calc_T2!$E$2:$E$36,0)),"") | D35: =IFERROR(INDEX(Calc_T2!$C$2:$C$36,MATCH($B35,Calc_T2!$E$2:$E$36,0)),"") | J35: 2017 | K35: =ROUND(SUMIFS(Data!$F:$F,Data!$A:$A,T2_Country,Data!$C:$C,$J35),2) -> 43.31 | L35: =ROUND(SUMIFS(Data!$G:$G,Data!$A:$A,T2_Country,Data!$C:$C,$J35),2) -> 56.28 | M35: =ROUND(SUMIFS(Data!$H:$H,Data!$A:$A,T2_Country,Data!$C:$C,$J35),2) -> 51.46 | N35: =ROUND(SUMIFS(Data!$I:$I,Data!$A:$A,T2_Country,Data!$C:$C,$J35),2) -> 56.12
B36: 6 | C36: =IFERROR(INDEX(Calc_T2!$A$2:$A$36,MATCH($B36,Calc_T2!$E$2:$E$36,0)),"") | D36: =IFERROR(INDEX(Calc_T2!$C$2:$C$36,MATCH($B36,Calc_T2!$E$2:$E$36,0)),"") | J36: 2018 | K36: =ROUND(SUMIFS(Data!$F:$F,Data!$A:$A,T2_Country,Data!$C:$C,$J36),2) -> 43.65 | L36: =ROUND(SUMIFS(Data!$G:$G,Data!$A:$A,T2_Country,Data!$C:$C,$J36),2) -> 57.31 | M36: =ROUND(SUMIFS(Data!$H:$H,Data!$A:$A,T2_Country,Data!$C:$C,$J36),2) -> 52.41 | N36: =ROUND(SUMIFS(Data!$I:$I,Data!$A:$A,T2_Country,Data!$C:$C,$J36),2) -> 54.3
B37: 7 | C37: =IFERROR(INDEX(Calc_T2!$A$2:$A$36,MATCH($B37,Calc_T2!$E$2:$E$36,0)),"") | D37: =IFERROR(INDEX(Calc_T2!$C$2:$C$36,MATCH($B37,Calc_T2!$E$2:$E$36,0)),"") | J37: 2019 | K37: =ROUND(SUMIFS(Data!$F:$F,Data!$A:$A,T2_Country,Data!$C:$C,$J37),2) -> 43.44 | L37: =ROUND(SUMIFS(Data!$G:$G,Data!$A:$A,T2_Country,Data!$C:$C,$J37),2) -> 56.62 | M37: =ROUND(SUMIFS(Data!$H:$H,Data!$A:$A,T2_Country,Data!$C:$C,$J37),2) -> 53.32 | N37: =ROUND(SUMIFS(Data!$I:$I,Data!$A:$A,T2_Country,Data!$C:$C,$J37),2) -> 55.81
B38: 8 | C38: =IFERROR(INDEX(Calc_T2!$A$2:$A$36,MATCH($B38,Calc_T2!$E$2:$E$36,0)),"") | D38: =IFERROR(INDEX(Calc_T2!$C$2:$C$36,MATCH($B38,Calc_T2!$E$2:$E$36,0)),"") | J38: 2020 | K38: =ROUND(SUMIFS(Data!$F:$F,Data!$A:$A,T2_Country,Data!$C:$C,$J38),2) -> 42.7 | L38: =ROUND(SUMIFS(Data!$G:$G,Data!$A:$A,T2_Country,Data!$C:$C,$J38),2) -> 55.19 | M38: =ROUND(SUMIFS(Data!$H:$H,Data!$A:$A,T2_Country,Data!$C:$C,$J38),2) -> 52.52 | N38: =ROUND(SUMIFS(Data!$I:$I,Data!$A:$A,T2_Country,Data!$C:$C,$J38),2) -> 53.58
B39: 9 | C39: =IFERROR(INDEX(Calc_T2!$A$2:$A$36,MATCH($B39,Calc_T2!$E$2:$E$36,0)),"") | D39: =IFERROR(INDEX(Calc_T2!$C$2:$C$36,MATCH($B39,Calc_T2!$E$2:$E$36,0)),"") | J39: 2021 | K39: =ROUND(SUMIFS(Data!$F:$F,Data!$A:$A,T2_Country,Data!$C:$C,$J39),2) -> 41.77 | L39: =ROUND(SUMIFS(Data!$G:$G,Data!$A:$A,T2_Country,Data!$C:$C,$J39),2) -> 53.8 | M39: =ROUND(SUMIFS(Data!$H:$H,Data!$A:$A,T2_Country,Data!$C:$C,$J39),2) -> 52.18 | N39: =ROUND(SUMIFS(Data!$I:$I,Data!$A:$A,T2_Country,Data!$C:$C,$J39),2) -> 55.62
B40: 10 | C40: =IFERROR(INDEX(Calc_T2!$A$2:$A$36,MATCH($B40,Calc_T2!$E$2:$E$36,0)),"") | D40: =IFERROR(INDEX(Calc_T2!$C$2:$C$36,MATCH($B40,Calc_T2!$E$2:$E$36,0)),"") | J40: 2022 | K40: =ROUND(SUMIFS(Data!$F:$F,Data!$A:$A,T2_Country,Data!$C:$C,$J40),2) -> 41.93 | L40: =ROUND(SUMIFS(Data!$G:$G,Data!$A:$A,T2_Country,Data!$C:$C,$J40),2) -> 55.06 | M40: =ROUND(SUMIFS(Data!$H:$H,Data!$A:$A,T2_Country,Data!$C:$C,$J40),2) -> 53.48 | N40: =ROUND(SUMIFS(Data!$I:$I,Data!$A:$A,T2_Country,Data!$C:$C,$J40),2) -> 53.02
J41: 2023 | K41: =ROUND(SUMIFS(Data!$F:$F,Data!$A:$A,T2_Country,Data!$C:$C,$J41),2) -> 41.07 | L41: =ROUND(SUMIFS(Data!$G:$G,Data!$A:$A,T2_Country,Data!$C:$C,$J41),2) -> 55.45 | M41: =ROUND(SUMIFS(Data!$H:$H,Data!$A:$A,T2_Country,Data!$C:$C,$J41),2) -> 52.86 | N41: =ROUND(SUMIFS(Data!$I:$I,Data!$A:$A,T2_Country,Data!$C:$C,$J41),2) -> 51.58
J42: 2024 | K42: =ROUND(SUMIFS(Data!$F:$F,Data!$A:$A,T2_Country,Data!$C:$C,$J42),2) -> 41.88 | L42: =ROUND(SUMIFS(Data!$G:$G,Data!$A:$A,T2_Country,Data!$C:$C,$J42),2) -> 56.29 | M42: =ROUND(SUMIFS(Data!$H:$H,Data!$A:$A,T2_Country,Data!$C:$C,$J42),2) -> 53.35 | N42: =ROUND(SUMIFS(Data!$I:$I,Data!$A:$A,T2_Country,Data!$C:$C,$J42),2) -> 52.47
B55: DETAILED COUNTRY TABLE (all years, selected country)
B56: Country | C56: Region | D56: Year | E56: Corruption | F56: Rule of Law | G56: Reg. Quality | H56: Pol. Stability | I56: Governance Avg | J56: Composite Risk Score | K56: Risk Tier
B57: =T2_Country -> India | C57: =Calc_T2!$H$1 -> South Asia | D57: 2013 | E57: =SUMIFS(Data!$F:$F,Data!$A:$A,T2_Country,Data!$C:$C,$D57) -> 38.33 | F57: =SUMIFS(Data!$G:$G,Data!$A:$A,T2_Country,Data!$C:$C,$D57) -> 54.97 | G57: =SUMIFS(Data!$H:$H,Data!$A:$A,T2_Country,Data!$C:$C,$D57) -> 48.99 | H57: =SUMIFS(Data!$I:$I,Data!$A:$A,T2_Country,Data!$C:$C,$D57) -> 45.89 | I57: =SUMIFS(Data!$J:$J,Data!$A:$A,T2_Country,Data!$C:$C,$D57) -> 47.04 | J57: =SUMIFS(Data!$K:$K,Data!$A:$A,T2_Country,Data!$C:$C,$D57) -> 52.96 | K57: =IF($J57>65,"High Risk",IF($J57>=40,"Medium Risk","Low Risk")) -> Medium Risk
B58: =T2_Country -> India | C58: =Calc_T2!$H$1 -> South Asia | D58: 2014 | E58: =SUMIFS(Data!$F:$F,Data!$A:$A,T2_Country,Data!$C:$C,$D58) -> 39.48 | F58: =SUMIFS(Data!$G:$G,Data!$A:$A,T2_Country,Data!$C:$C,$D58) -> 54.11 | G58: =SUMIFS(Data!$H:$H,Data!$A:$A,T2_Country,Data!$C:$C,$D58) -> 48.86 | H58: =SUMIFS(Data!$I:$I,Data!$A:$A,T2_Country,Data!$C:$C,$D58) -> 51.93 | I58: =SUMIFS(Data!$J:$J,Data!$A:$A,T2_Country,Data!$C:$C,$D58) -> 48.59 | J58: =SUMIFS(Data!$K:$K,Data!$A:$A,T2_Country,Data!$C:$C,$D58) -> 51.41 | K58: =IF($J58>65,"High Risk",IF($J58>=40,"Medium Risk","Low Risk")) -> Medium Risk
B59: =T2_Country -> India | C59: =Calc_T2!$H$1 -> South Asia | D59: 2015 | E59: =SUMIFS(Data!$F:$F,Data!$A:$A,T2_Country,Data!$C:$C,$D59) -> 40.87 | F59: =SUMIFS(Data!$G:$G,Data!$A:$A,T2_Country,Data!$C:$C,$D59) -> 54.6 | G59: =SUMIFS(Data!$H:$H,Data!$A:$A,T2_Country,Data!$C:$C,$D59) -> 49.65 | H59: =SUMIFS(Data!$I:$I,Data!$A:$A,T2_Country,Data!$C:$C,$D59) -> 52.88 | I59: =SUMIFS(Data!$J:$J,Data!$A:$A,T2_Country,Data!$C:$C,$D59) -> 49.5 | J59: =SUMIFS(Data!$K:$K,Data!$A:$A,T2_Country,Data!$C:$C,$D59) -> 50.5 | K59: =IF($J59>65,"High Risk",IF($J59>=40,"Medium Risk","Low Risk")) -> Medium Risk
B60: =T2_Country -> India | C60: =Calc_T2!$H$1 -> South Asia | D60: 2016 | E60: =SUMIFS(Data!$F:$F,Data!$A:$A,T2_Country,Data!$C:$C,$D60) -> 42.08 | F60: =SUMIFS(Data!$G:$G,Data!$A:$A,T2_Country,Data!$C:$C,$D60) -> 55.55 | G60: =SUMIFS(Data!$H:$H,Data!$A:$A,T2_Country,Data!$C:$C,$D60) -> 50.86 | H60: =SUMIFS(Data!$I:$I,Data!$A:$A,T2_Country,Data!$C:$C,$D60) -> 53.32 | I60: =SUMIFS(Data!$J:$J,Data!$A:$A,T2_Country,Data!$C:$C,$D60) -> 50.45 | J60: =SUMIFS(Data!$K:$K,Data!$A:$A,T2_Country,Data!$C:$C,$D60) -> 49.55 | K60: =IF($J60>65,"High Risk",IF($J60>=40,"Medium Risk","Low Risk")) -> Medium Risk
...

Sheet Data
A1: Country Name | B1: Country Code | C1: Year | D1: Region | E1: Income_Group | F1: Control_of_Corruption | G1: Rule_of_Law | H1: Regulatory_Quality | I1: Political_Stability | J1: Governance_Avg | K1: Composite_Risk_Score | L1: Risk_Tier | M1: GDP_per_Capita_USD | N1: Risk_Tier_Calc | O1: Match_RegionIncome_T1
A2: Argentina | B2: ARG | C2: 2013 | D2: Latin America & Caribbean | E2: Upper middle income | F2: 37.38 | G2: 47.05 | H2: 41.69 | I2: 66.45 | J2: 48.14 | K2: 51.86 | L2: Medium Risk | M2: 12963.68 | N2: =IF(K2>65,"High Risk",IF(K2>=40,"Medium Risk","Low Risk")) -> Medium Risk | O2: =AND(OR($D2=T1_Region,T1_Region="All Regions"),OR($E2=T1_Income,T1_Income="All Income Groups")) -> TRUE
A3: Argentina | B3: ARG | C3: 2014 | D3: Latin America & Caribbean | E3: Upper middle income | F3: 34.37 | G3: 44.4 | H3: 38.89 | I3: 65.67 | J3: 45.83 | K3: 54.17 | L3: Medium Risk | M3: 12233.14 | N3: =IF(K3>65,"High Risk",IF(K3>=40,"Medium Risk","Low Risk")) -> Medium Risk | O3: =AND(OR($D3=T1_Region,T1_Region="All Regions"),OR($E3=T1_Income,T1_Income="All Income Groups")) -> TRUE
A4: Argentina | B4: ARG | C4: 2015 | D4: Latin America & Caribbean | E4: Upper middle income | F4: 34.8 | G4: 48.92 | H4: 42.29 | I4: 65.37 | J4: 47.84 | K4: 52.16 | L4: Medium Risk | M4: 13679.63 | N4: =IF(K4>65,"High Risk",IF(K4>=40,"Medium Risk","Low Risk")) -> Medium Risk | O4: =AND(OR($D4=T1_Region,T1_Region="All Regions"),OR($E4=T1_Income,T1_Income="All Income Groups")) -> TRUE
A5: Argentina | B5: ARG | C5: 2016 | D5: Latin America & Caribbean | E5: Upper middle income | F5: 43.41 | G5: 52.89 | H5: 50.88 | I5: 69.2 | J5: 54.1 | K5: 45.9 | L5: Medium Risk | M5: 12699.96 | N5: =IF(K5>65,"High Risk",IF(K5>=40,"Medium Risk","Low Risk")) -> Medium Risk | O5: =AND(OR($D5=T1_Region,T1_Region="All Regions"),OR($E5=T1_Income,T1_Income="All Income Groups")) -> TRUE
A6: Argentina | B6: ARG | C6: 2017 | D6: Latin America & Caribbean | E6: Upper middle income | F6: 44.25 | G6: 54 | H6: 52.96 | I6: 69.98 | J6: 55.3 | K6: 44.7 | L6: Medium Risk | M6: 14532.5 | N6: =IF(K6>65,"High Risk",IF(K6>=40,"Medium Risk","Low Risk")) -> Medium Risk | O6: =AND(OR($D6=T1_Region,T1_Region="All Regions"),OR($E6=T1_Income,T1_Income="All Income Groups")) -> TRUE
A7: Argentina | B7: ARG | C7: 2018 | D7: Latin America & Caribbean | E7: Upper middle income | F7: 47.74 | G7: 53.48 | H7: 51.86 | I7: 67.95 | J7: 55.26 | K7: 44.74 | L7: Medium Risk | M7: 11752.8 | N7: =IF(K7>65,"High Risk",IF(K7>=40,"Medium Risk","Low Risk")) -> Medium Risk | O7: =AND(OR($D7=T1_Region,T1_Region="All Regions"),OR($E7=T1_Income,T1_Income="All Income Groups")) -> TRUE
A8: Argentina | B8: ARG | C8: 2019 | D8: Latin America & Caribbean | E8: Upper middle income | F8: 46.14 | G8: 51.15 | H8: 47.78 | I8: 66.87 | J8: 52.98 | K8: 47.02 | L8: Medium Risk | M8: 9955.97 | N8: =IF(K8>65,"High Risk",IF(K8>=40,"Medium Risk","Low Risk")) -> Medium Risk | O8: =AND(OR($D8=T1_Region,T1_Region="All Regions"),OR($E8=T1_Income,T1_Income="All Income Groups")) -> TRUE
A9: Argentina | B9: ARG | C9: 2020 | D9: Latin America & Caribbean | E9: Upper middle income | F9: 45.13 | G9: 51.96 | H9: 46.23 | I9: 66.84 | J9: 52.54 | K9: 47.46 | L9: Medium Risk | M9: 8535.6 | N9: =IF(K9>65,"High Risk",IF(K9>=40,"Medium Risk","Low Risk")) -> Medium Risk | O9: =AND(OR($D9=T1_Region,T1_Region="All Regions"),OR($E9=T1_Income,T1_Income="All Income Groups")) -> TRUE
A10: Argentina | B10: ARG | C10: 2021 | D10: Latin America & Caribbean | E10: Upper middle income | F10: 41.23 | G10: 51.73 | H10: 45.65 | I10: 67.47 | J10: 51.52 | K10: 48.48 | L10: Medium Risk | M10: 10738.02 | N10: =IF(K10>65,"High Risk",IF(K10>=40,"Medium Risk","Low Risk")) -> Medium Risk | O10: =AND(OR($D10=T1_Region,T1_Region="All Regions"),OR($E10=T1_Income,T1_Income="All Income Groups")) -> TRUE
A11: Argentina | B11: ARG | C11: 2022 | D11: Latin America & Caribbean | E11: Upper middle income | F11: 40.97 | G11: 51.95 | H11: 45.73 | I11: 66.88 | J11: 51.38 | K11: 48.62 | L11: Medium Risk | M11: 13962.19 | N11: =IF(K11>65,"High Risk",IF(K11>=40,"Medium Risk","Low Risk")) -> Medium Risk | O11: =AND(OR($D11=T1_Region,T1_Region="All Regions"),OR($E11=T1_Income,T1_Income="All Income Groups")) -> TRUE
A12: Argentina | B12: ARG | C12: 2023 | D12: Latin America & Caribbean | E12: Upper middle income | F12: 40.69 | G12: 52.87 | H12: 46.87 | I12: 65.54 | J12: 51.49 | K12: 48.51 | L12: Medium Risk | M12: 14261.85 | N12: =IF(K12>65,"High Risk",IF(K12>=40,"Medium Risk","Low Risk")) -> Medium Risk | O12: =AND(OR($D12=T1_Region,T1_Region="All Regions"),OR($E12=T1_Income,T1_Income="All Income Groups")) -> TRUE
A13: Argentina | B13: ARG | C13: 2024 | D13: Latin America & Caribbean | E13: Upper middle income | F13: 41.26 | G13: 52.64 | H13: 51.16 | I13: 62.99 | J13: 52.01 | K13: 47.99 | L13: Medium Risk | M13: 13969.78 | N13: =IF(K13>65,"High Risk",IF(K13>=40,"Medium Risk","Low Risk")) -> Medium Risk | O13: =AND(OR($D13=T1_Region,T1_Region="All Regions"),OR($E13=T1_Income,T1_Income="All Income Groups")) -> TRUE
... A421: United States | B421: USA | C421: 2024 | D421: North America | E421: High income | F421: 69.86 | G421: 73.52 | H421: 76.19 | I421: 64.27 | J421: 70.96 | K421: 29.04 | L421: Low Risk | M421: 86169.66 | N421: =IF(K421>65,"High Risk",IF(K421>=40,"Medium Risk","Low Risk")) -> Low Risk | O421: =AND(OR($D421=T1_Region,T1_Region="All Regions"),OR($E421=T1_Income,T1_Income="All Income Groups")) -> TRUE

Sheet CountryMeta
A1: Country Name | B1: Country Code | C1: Region | D1: Income_Group
A2: Argentina | B2: ARG | C2: Latin America & Caribbean | D2: Upper middle income
A3: Australia | B3: AUS | C3: East Asia & Pacific | D3: High income
A4: Bangladesh | B4: BGD | C4: South Asia | D4: Lower middle income
A5: Brazil | B5: BRA | C5: Latin America & Caribbean | D5: Upper middle income
A6: Canada | B6: CAN | C6: North America | D6: High income
A7: Chile | B7: CHL | C7: Latin America & Caribbean | D7: High income
A8: China | B8: CHN | C8: East Asia & Pacific | D8: Upper middle income
A9: Colombia | B9: COL | C9: Latin America & Caribbean | D9: Upper middle income
A10: Congo, Dem. Rep. | B10: COD | C10: Sub-Saharan Africa | D10: Low income
A11: Egypt, Arab Rep. | B11: EGY | C11: Middle East & North Africa | D11: Lower middle income
A12: Ethiopia | B12: ETH | C12: Sub-Saharan Africa | D12: Low income
... A36: United States | B36: USA | C36: North America | D36: High income

Sheet Lookups
A1: Regions | B1: Income Groups | C1: Years
A2: All Regions | B2: All Income Groups | C2: 2013
A3: East Asia & Pacific | B3: High income | C3: 2014
A4: Europe & Central Asia | B4: Upper middle income | C4: 2015
A5: Latin America & Caribbean | B5: Lower middle income | C5: 2016
A6: Middle East & North Africa | B6: Low income | C6: 2017
A7: North America | C7: 2018
A8: South Asia | C8: 2019
A9: Sub-Saharan Africa | C9: 2020
C10: 2021
C11: 2022
C12: 2023
C13: 2024

Sheet Calc_T1
A1: Country | B1: Region | C1: IncomeGroup | D1: Included | E1: ScoreYear | F1: GDPYear | G1: Score2013 | H1: Score2024 | I1: Change_13_24 | J1: Tier | K1: IncludedScore | L1: IncludedChange | M1: RankDesc | N1: X_East Asia & | O1: Y_East Asia & | P1: X_Europe & Cen | Q1: Y_Europe & Cen | R1: X_Latin Americ | S1: Y_Latin Americ | T1: X_Middle East | U1: Y_Middle East | V1: X_North Americ | W1: Y_North Americ | X1: X_South Asia | Y1: Y_South Asia | Z1: X_Sub-Saharan | AA1: Y_Sub-Saharan
A2: =CountryMeta!A2 -> Argentina | B2: =CountryMeta!C2 -> Latin America & Caribbean | C2: =CountryMeta!D2 -> Upper middle income | D2: =AND(OR($B2=T1_Region,T1_Region="All Regions"),OR($C2=T1_Income,T1_Income="All Income Groups")) -> TRUE | E2: =SUMIFS(Data!$K:$K,Data!$A:$A,$A2,Data!$C:$C,T1_Year) -> 47.99 | F2: =SUMIFS(Data!$M:$M,Data!$A:$A,$A2,Data!$C:$C,T1_Year) -> 13969.78 | G2: =SUMIFS(Data!$K:$K,Data!$A:$A,$A2,Data!$C:$C,2013) -> 51.86 | H2: =SUMIFS(Data!$K:$K,Data!$A:$A,$A2,Data!$C:$C,2024) -> 47.99 | I2: =H2-G2 -> -3.87 | J2: =IF($E2>65,"High Risk",IF($E2>=40,"Medium Risk","Low Risk")) -> Medium Risk | K2: =IF($D2,$E2,"") -> 47.99 | L2: =IF($D2,$I2,"") -> -3.87 | M2: =IFERROR(RANK($K2,$K$2:$K$36,0),"") -> 18 | N2: =IF(AND($D2,$B2="East Asia & Pacific"),$F2,"") | O2: =IF(AND($D2,$B2="East Asia & Pacific"),$E2,"") | P2: =IF(AND($D2,$B2="Europe & Central Asia"),$F2,"") | Q2: =IF(AND($D2,$B2="Europe & Central Asia"),$E2,"") | R2: =IF(AND($D2,$B2="Latin America & Caribbean"),$F2,"") -> 13969.78 | S2: =IF(AND($D2,$B2="Latin America & Caribbean"),$E2,"") -> 47.99 | T2: =IF(AND($D2,$B2="Middle East & North Africa"),$F2,"") | U2: =IF(AND($D2,$B2="Middle East & North Africa"),$E2,"") | V2: =IF(AND($D2,$B2="North America"),$F2,"") | W2: =IF(AND($D2,$B2="North America"),$E2,"") | X2: =IF(AND($D2,$B2="South Asia"),$F2,"") | Y2: =IF(AND($D2,$B2="South Asia"),$E2,"") | Z2: =IF(AND($D2,$B2="Sub-Saharan Africa"),$F2,"") | AA2: =IF(AND($D2,$B2="Sub-Saharan Africa"),$E2,"")
A3: =CountryMeta!A3 -> Australia | B3: =CountryMeta!C3 -> East Asia & Pacific | C3: =CountryMeta!D3 -> High income | D3: =AND(OR($B3=T1_Region,T1_Region="All Regions"),OR($C3=T1_Income,T1_Income="All Income Groups")) -> TRUE | E3: =SUMIFS(Data!$K:$K,Data!$A:$A,$A3,Data!$C:$C,T1_Year) -> 17.73 | F3: =SUMIFS(Data!$M:$M,Data!$A:$A,$A3,Data!$C:$C,T1_Year) -> 64609.99 | G3: =SUMIFS(Data!$K:$K,Data!$A:$A,$A3,Data!$C:$C,2013) -> 16.31 | H3: =SUMIFS(Data!$K:$K,Data!$A:$A,$A3,Data!$C:$C,2024) -> 17.73 | I3: =H3-G3 -> 1.42 | J3: =IF($E3>65,"High Risk",IF($E3>=40,"Medium Risk","Low Risk")) -> Low Risk | K3: =IF($D3,$E3,"") -> 17.73 | L3: =IF($D3,$I3,"") -> 1.42 | M3: =IFERROR(RANK($K3,$K$2:$K$36,0),"") -> 35 | N3: =IF(AND($D3,$B3="East Asia & Pacific"),$F3,"") -> 64609.99 | O3: =IF(AND($D3,$B3="East Asia & Pacific"),$E3,"") -> 17.73 | P3: =IF(AND($D3,$B3="Europe & Central Asia"),$F3,"") | Q3: =IF(AND($D3,$B3="Europe & Central Asia"),$E3,"") | R3: =IF(AND($D3,$B3="Latin America & Caribbean"),$F3,"") | S3: =IF(AND($D3,$B3="Latin America & Caribbean"),$E3,"") | T3: =IF(AND($D3,$B3="Middle East & North Africa"),$F3,"") | U3: =IF(AND($D3,$B3="Middle East & North Africa"),$E3,"") | V3: =IF(AND($D3,$B3="North America"),$F3,"") | W3: =IF(AND($D3,$B3="North America"),$E3,"") | X3: =IF(AND($D3,$B3="South Asia"),$F3,"") | Y3: =IF(AND($D3,$B3="South Asia"),$E3,"") | Z3: =IF(AND($D3,$B3="Sub-Saharan Africa"),$F3,"") | AA3: =IF(AND($D3,$B3="Sub-Saharan Africa"),$E3,"")
A4: =CountryMeta!A4 -> Bangladesh | B4: =CountryMeta!C4 -> South Asia | C4: =CountryMeta!D4 -> Lower middle income | D4: =AND(OR($B4=T1_Region,T1_Region="All Regions"),OR($C4=T1_Income,T1_Income="All Income Groups")) -> TRUE | E4: =SUMIFS(Data!$K:$K,Data!$A:$A,$A4,Data!$C:$C,T1_Year) -> 63.31 | F4: =SUMIFS(Data!$M:$M,Data!$A:$A,$A4,Data!$C:$C,T1_Year) -> 2593.42 | G4: =SUMIFS(Data!$K:$K,Data!$A:$A,$A4,Data!$C:$C,2013) -> 64.84 | H4: =SUMIFS(Data!$K:$K,Data!$A:$A,$A4,Data!$C:$C,2024) -> 63.31 | I4: =H4-G4 -> -1.53 | J4: =IF($E4>65,"High Risk",IF($E4>=40,"Medium Risk","Low Risk")) -> Medium Risk | K4: =IF($D4,$E4,"") -> 63.31 | L4: =IF($D4,$I4,"") -> -1.53 | M4: =IFERROR(RANK($K4,$K$2:$K$36,0),"") -> 5 | N4: =IF(AND($D4,$B4="East Asia & Pacific"),$F4,"") | O4: =IF(AND($D4,$B4="East Asia & Pacific"),$E4,"") | P4: =IF(AND($D4,$B4="Europe & Central Asia"),$F4,"") | Q4: =IF(AND($D4,$B4="Europe & Central Asia"),$E4,"") | R4: =IF(AND($D4,$B4="Latin America & Caribbean"),$F4,"") | S4: =IF(AND($D4,$B4="Latin America & Caribbean"),$E4,"") | T4: =IF(AND($D4,$B4="Middle East & North Africa"),$F4,"") | U4: =IF(AND($D4,$B4="Middle East & North Africa"),$E4,"") | V4: =IF(AND($D4,$B4="North America"),$F4,"") | W4: =IF(AND($D4,$B4="North America"),$E4,"") | X4: =IF(AND($D4,$B4="South Asia"),$F4,"") -> 2593.42 | Y4: =IF(AND($D4,$B4="South Asia"),$E4,"") -> 63.31 | Z4: =IF(AND($D4,$B4="Sub-Saharan Africa"),$F4,"") | AA4: =IF(AND($D4,$B4="Sub-Saharan Africa"),$E4,"")
A5: =CountryMeta!A5 -> Brazil | B5: =CountryMeta!C5 -> Latin America & Caribbean | C5: =CountryMeta!D5 -> Upper middle income | D5: =AND(OR($B5=T1_Region,T1_Region="All Regions"),OR($C5=T1_Income,T1_Income="All Income Groups")) -> TRUE | E5: =SUMIFS(Data!$K:$K,Data!$A:$A,$A5,Data!$C:$C,T1_Year) -> 50.98 | F5: =SUMIFS(Data!$M:$M,Data!$A:$A,$A5,Data!$C:$C,T1_Year) -> 10310.55 | G5: =SUMIFS(Data!$K:$K,Data!$A:$A,$A5,Data!$C:$C,2013) -> 45.54 | H5: =SUMIFS(Data!$K:$K,Data!$A:$A,$A5,Data!$C:$C,2024) -> 50.98 | I5: =H5-G5 -> 5.44 | J5: =IF($E5>65,"High Risk",IF($E5>=40,"Medium Risk","Low Risk")) -> Medium Risk | K5: =IF($D5,$E5,"") -> 50.98 | L5: =IF($D5,$I5,"") -> 5.44 | M5: =IFERROR(RANK($K5,$K$2:$K$36,0),"") -> 14 | N5: =IF(AND($D5,$B5="East Asia & Pacific"),$F5,"") | O5: =IF(AND($D5,$B5="East Asia & Pacific"),$E5,"") | P5: =IF(AND($D5,$B5="Europe & Central Asia"),$F5,"") | Q5: =IF(AND($D5,$B5="Europe & Central Asia"),$E5,"") | R5: =IF(AND($D5,$B5="Latin America & Caribbean"),$F5,"") -> 10310.55 | S5: =IF(AND($D5,$B5="Latin America & Caribbean"),$E5,"") -> 50.98 | T5: =IF(AND($D5,$B5="Middle East & North Africa"),$F5,"") | U5: =IF(AND($D5,$B5="Middle East & North Africa"),$E5,"") | V5: =IF(AND($D5,$B5="North America"),$F5,"") | W5: =IF(AND($D5,$B5="North America"),$E5,"") | X5: =IF(AND($D5,$B5="South Asia"),$F5,"") | Y5: =IF(AND($D5,$B5="South Asia"),$E5,"") | Z5: =IF(AND($D5,$B5="Sub-Saharan Africa"),$F5,"") | AA5: =IF(AND($D5,$B5="Sub-Saharan Africa"),$E5,"")
A6: =CountryMeta!A6 -> Canada | B6: =CountryMeta!C6 -> North America | C6: =CountryMeta!D6 -> High income | D6: =AND(OR($B6=T1_Region,T1_Region="All Regions"),OR($C6=T1_Income,T1_Income="All Income Groups")) -> TRUE | E6: =SUMIFS(Data!$K:$K,Data!$A:$A,$A6,Data!$C:$C,T1_Year) -> 21.14 | F6: =SUMIFS(Data!$M:$M,Data!$A:$A,$A6,Data!$C:$C,T1_Year) -> 55015.71 | G6: =SUMIFS(Data!$K:$K,Data!$A:$A,$A6,Data!$C:$C,2013) -> 16.26 | H6: =SUMIFS(Data!$K:$K,Data!$A:$A,$A6,Data!$C:$C,2024) -> 21.14 | I6: =H6-G6 -> 4.88 | J6: =IF($E6>65,"High Risk",IF($E6>=40,"Medium Risk","Low Risk")) -> Low Risk | K6: =IF($D6,$E6,"") -> 21.14 | L6: =IF($D6,$I6,"") -> 4.88 | M6: =IFERROR(RANK($K6,$K$2:$K$36,0),"") -> 33 | N6: =IF(AND($D6,$B6="East Asia & Pacific"),$F6,"") | O6: =IF(AND($D6,$B6="East Asia & Pacific"),$E6,"") | P6: =IF(AND($D6,$B6="Europe & Central Asia"),$F6,"") | Q6: =IF(AND($D6,$B6="Europe & Central Asia"),$E6,"") | R6: =IF(AND($D6,$B6="Latin America & Caribbean"),$F6,"") | S6: =IF(AND($D6,$B6="Latin America & Caribbean"),$E6,"") | T6: =IF(AND($D6,$B6="Middle East & North Africa"),$F6,"") | U6: =IF(AND($D6,$B6="Middle East & North Africa"),$E6,"") | V6: =IF(AND($D6,$B6="North America"),$F6,"") -> 55015.71 | W6: =IF(AND($D6,$B6="North America"),$E6,"") -> 21.14 | X6: =IF(AND($D6,$B6="South Asia"),$F6,"") | Y6: =IF(AND($D6,$B6="South Asia"),$E6,"") | Z6: =IF(AND($D6,$B6="Sub-Saharan Africa"),$F6,"") | AA6: =IF(AND($D6,$B6="Sub-Saharan Africa"),$E6,"")
A7: =CountryMeta!A7 -> Chile | B7: =CountryMeta!C7 -> Latin America & Caribbean | C7: =CountryMeta!D7 -> High income | D7: =AND(OR($B7=T1_Region,T1_Region="All Regions"),OR($C7=T1_Income,T1_Income="All Income Groups")) -> TRUE | E7: =SUMIFS(Data!$K:$K,Data!$A:$A,$A7,Data!$C:$C,T1_Year) -> 31.44 | F7: =SUMIFS(Data!$M:$M,Data!$A:$A,$A7,Data!$C:$C,T1_Year) -> 16658.97 | G7: =SUMIFS(Data!$K:$K,Data!$A:$A,$A7,Data!$C:$C,2013) -> 23.37 | H7: =SUMIFS(Data!$K:$K,Data!$A:$A,$A7,Data!$C:$C,2024) -> 31.44 | I7: =H7-G7 -> 8.07 | J7: =IF($E7>65,"High Risk",IF($E7>=40,"Medium Risk","Low Risk")) -> Low Risk | K7: =IF($D7,$E7,"") -> 31.44 | L7: =IF($D7,$I7,"") -> 8.07 | M7: =IFERROR(RANK($K7,$K$2:$K$36,0),"") -> 27 | N7: =IF(AND($D7,$B7="East Asia & Pacific"),$F7,"") | O7: =IF(AND($D7,$B7="East Asia & Pacific"),$E7,"") | P7: =IF(AND($D7,$B7="Europe & Central Asia"),$F7,"") | Q7: =IF(AND($D7,$B7="Europe & Central Asia"),$E7,"") | R7: =IF(AND($D7,$B7="Latin America & Caribbean"),$F7,"") -> 16658.97 | S7: =IF(AND($D7,$B7="Latin America & Caribbean"),$E7,"") -> 31.44 | T7: =IF(AND($D7,$B7="Middle East & North Africa"),$F7,"") | U7: =IF(AND($D7,$B7="Middle East & North Africa"),$E7,"") | V7: =IF(AND($D7,$B7="North America"),$F7,"") | W7: =IF(AND($D7,$B7="North America"),$E7,"") | X7: =IF(AND($D7,$B7="South Asia"),$F7,"") | Y7: =IF(AND($D7,$B7="South Asia"),$E7,"") | Z7: =IF(AND($D7,$B7="Sub-Saharan Africa"),$F7,"") | AA7: =IF(AND($D7,$B7="Sub-Saharan Africa"),$E7,"")
A8: =CountryMeta!A8 -> China | B8: =CountryMeta!C8 -> East Asia & Pacific | C8: =CountryMeta!D8 -> Upper middle income | D8: =AND(OR($B8=T1_Region,T1_Region="All Regions"),OR($C8=T1_Income,T1_Income="All Income Groups")) -> TRUE | E8: =SUMIFS(Data!$K:$K,Data!$A:$A,$A8,Data!$C:$C,T1_Year) -> 46.59 | F8: =SUMIFS(Data!$M:$M,Data!$A:$A,$A8,Data!$C:$C,T1_Year) -> 13293.12 | G8: =SUMIFS(Data!$K:$K,Data!$A:$A,$A8,Data!$C:$C,2013) -> 52.78 | H8: =SUMIFS(Data!$K:$K,Data!$A:$A,$A8,Data!$C:$C,2024) -> 46.59 | I8: =H8-G8 -> -6.19 | J8: =IF($E8>65,"High Risk",IF($E8>=40,"Medium Risk","Low Risk")) -> Medium Risk | K8: =IF($D8,$E8,"") -> 46.59 | L8: =IF($D8,$I8,"") -> -6.19 | M8: =IFERROR(RANK($K8,$K$2:$K$36,0),"") -> 21 | N8: =IF(AND($D8,$B8="East Asia & Pacific"),$F8,"") -> 13293.12 | O8: =IF(AND($D8,$B8="East Asia & Pacific"),$E8,"") -> 46.59 | P8: =IF(AND($D8,$B8="Europe & Central Asia"),$F8,"") | Q8: =IF(AND($D8,$B8="Europe & Central Asia"),$E8,"") | R8: =IF(AND($D8,$B8="Latin America & Caribbean"),$F8,"") | S8: =IF(AND($D8,$B8="Latin America & Caribbean"),$E8,"") | T8: =IF(AND($D8,$B8="Middle East & North Africa"),$F8,"") | U8: =IF(AND($D8,$B8="Middle East & North Africa"),$E8,"") | V8: =IF(AND($D8,$B8="North America"),$F8,"") | W8: =IF(AND($D8,$B8="North America"),$E8,"") | X8: =IF(AND($D8,$B8="South Asia"),$F8,"") | Y8: =IF(AND($D8,$B8="South Asia"),$E8,"") | Z8: =IF(AND($D8,$B8="Sub-Saharan Africa"),$F8,"") | AA8: =IF(AND($D8,$B8="Sub-Saharan Africa"),$E8,"")
A9: =CountryMeta!A9 -> Colombia | B9: =CountryMeta!C9 -> Latin America & Caribbean | C9: =CountryMeta!D9 -> Upper middle income | D9: =AND(OR($B9=T1_Region,T1_Region="All Regions"),OR($C9=T1_Income,T1_Income="All Income Groups")) -> TRUE | E9: =SUMIFS(Data!$K:$K,Data!$A:$A,$A9,Data!$C:$C,T1_Year) -> 51.59 | F9: =SUMIFS(Data!$M:$M,Data!$A:$A,$A9,Data!$C:$C,T1_Year) -> 7951.09 | G9: =SUMIFS(Data!$K:$K,Data!$A:$A,$A9,Data!$C:$C,2013) -> 52.54 | H9: =SUMIFS(Data!$K:$K,Data!$A:$A,$A9,Data!$C:$C,2024) -> 51.59 | I9: =H9-G9 -> -0.95 | J9: =IF($E9>65,"High Risk",IF($E9>=40,"Medium Risk","Low Risk")) -> Medium Risk | K9: =IF($D9,$E9,"") -> 51.59 | L9: =IF($D9,$I9,"") -> -0.95 | M9: =IFERROR(RANK($K9,$K$2:$K$36,0),"") -> 13 | N9: =IF(AND($D9,$B9="East Asia & Pacific"),$F9,"") | O9: =IF(AND($D9,$B9="East Asia & Pacific"),$E9,"") | P9: =IF(AND($D9,$B9="Europe & Central Asia"),$F9,"") | Q9: =IF(AND($D9,$B9="Europe & Central Asia"),$E9,"") | R9: =IF(AND($D9,$B9="Latin America & Caribbean"),$F9,"") -> 7951.09 | S9: =IF(AND($D9,$B9="Latin America & Caribbean"),$E9,"") -> 51.59 | T9: =IF(AND($D9,$B9="Middle East & North Africa"),$F9,"") | U9: =IF(AND($D9,$B9="Middle East & North Africa"),$E9,"") | V9: =IF(AND($D9,$B9="North America"),$F9,"") | W9: =IF(AND($D9,$B9="North America"),$E9,"") | X9: =IF(AND($D9,$B9="South Asia"),$F9,"") | Y9: =IF(AND($D9,$B9="South Asia"),$E9,"") | Z9: =IF(AND($D9,$B9="Sub-Saharan Africa"),$F9,"") | AA9: =IF(AND($D9,$B9="Sub-Saharan Africa"),$E9,"")
A10: =CountryMeta!A10 -> Congo, Dem. Rep. | B10: =CountryMeta!C10 -> Sub-Saharan Africa | C10: =CountryMeta!D10 -> Low income | D10: =AND(OR($B10=T1_Region,T1_Region="All Regions"),OR($C10=T1_Income,T1_Income="All Income Groups")) -> TRUE | E10: =SUMIFS(Data!$K:$K,Data!$A:$A,$A10,Data!$C:$C,T1_Year) -> 72.39 | F10: =SUMIFS(Data!$M:$M,Data!$A:$A,$A10,Data!$C:$C,T1_Year) -> 692.89 | G10: =SUMIFS(Data!$K:$K,Data!$A:$A,$A10,Data!$C:$C,2013) -> 71.92 | H10: =SUMIFS(Data!$K:$K,Data!$A:$A,$A10,Data!$C:$C,2024) -> 72.39 | I10: =H10-G10 -> 0.47 | J10: =IF($E10>65,"High Risk",IF($E10>=40,"Medium Risk","Low Risk")) -> High Risk | K10: =IF($D10,$E10,"") -> 72.39 | L10: =IF($D10,$I10,"") -> 0.47 | M10: =IFERROR(RANK($K10,$K$2:$K$36,0),"") -> 1 | N10: =IF(AND($D10,$B10="East Asia & Pacific"),$F10,"") | O10: =IF(AND($D10,$B10="East Asia & Pacific"),$E10,"") | P10: =IF(AND($D10,$B10="Europe & Central Asia"),$F10,"") | Q10: =IF(AND($D10,$B10="Europe & Central Asia"),$E10,"") | R10: =IF(AND($D10,$B10="Latin America & Caribbean"),$F10,"") | S10: =IF(AND($D10,$B10="Latin America & Caribbean"),$E10,"") | T10: =IF(AND($D10,$B10="Middle East & North Africa"),$F10,"") | U10: =IF(AND($D10,$B10="Middle East & North Africa"),$E10,"") | V10: =IF(AND($D10,$B10="North America"),$F10,"") | W10: =IF(AND($D10,$B10="North America"),$E10,"") | X10: =IF(AND($D10,$B10="South Asia"),$F10,"") | Y10: =IF(AND($D10,$B10="South Asia"),$E10,"") | Z10: =IF(AND($D10,$B10="Sub-Saharan Africa"),$F10,"") -> 692.89 | AA10: =IF(AND($D10,$B10="Sub-Saharan Africa"),$E10,"") -> 72.39
A11: =CountryMeta!A11 -> Egypt, Arab Rep. | B11: =CountryMeta!C11 -> Middle East & North Africa | C11: =CountryMeta!D11 -> Lower middle income | D11: =AND(OR($B11=T1_Region,T1_Region="All Regions"),OR($C11=T1_Income,T1_Income="All Income Groups")) -> TRUE | E11: =SUMIFS(Data!$K:$K,Data!$A:$A,$A11,Data!$C:$C,T1_Year) -> 57.17 | F11: =SUMIFS(Data!$M:$M,Data!$A:$A,$A11,Data!$C:$C,T1_Year) -> 3338.47 | G11: =SUMIFS(Data!$K:$K,Data!$A:$A,$A11,Data!$C:$C,2013) -> 60.52 | H11: =SUMIFS(Data!$K:$K,Data!$A:$A,$A11,Data!$C:$C,2024) -> 57.17 | I11: =H11-G11 -> -3.35 | J11: =IF($E11>65,"High Risk",IF($E11>=40,"Medium Risk","Low Risk")) -> Medium Risk | K11: =IF($D11,$E11,"") -> 57.17 | L11: =IF($D11,$I11,"") -> -3.35 | M11: =IFERROR(RANK($K11,$K$2:$K$36,0),"") -> 8 | N11: =IF(AND($D11,$B11="East Asia & Pacific"),$F11,"") | O11: =IF(AND($D11,$B11="East Asia & Pacific"),$E11,"") | P11: =IF(AND($D11,$B11="Europe & Central Asia"),$F11,"") | Q11: =IF(AND($D11,$B11="Europe & Central Asia"),$E11,"") | R11: =IF(AND($D11,$B11="Latin America & Caribbean"),$F11,"") | S11: =IF(AND($D11,$B11="Latin America & Caribbean"),$E11,"") | T11: =IF(AND($D11,$B11="Middle East & North Africa"),$F11,"") -> 3338.47 | U11: =IF(AND($D11,$B11="Middle East & North Africa"),$E11,"") -> 57.17 | V11: =IF(AND($D11,$B11="North America"),$F11,"") | W11: =IF(AND($D11,$B11="North America"),$E11,"") | X11: =IF(AND($D11,$B11="South Asia"),$F11,"") | Y11: =IF(AND($D11,$B11="South Asia"),$E11,"") | Z11: =IF(AND($D11,$B11="Sub-Saharan Africa"),$F11,"") | AA11: =IF(AND($D11,$B11="Sub-Saharan Africa"),$E11,"")
A12: =CountryMeta!A12 -> Ethiopia | B12: =CountryMeta!C12 -> Sub-Saharan Africa | C12: =CountryMeta!D12 -> Low income | D12: =AND(OR($B12=T1_Region,T1_Region="All Regions"),OR($C12=T1_Income,T1_Income="All Income Groups")) -> TRUE | E12: =SUMIFS(Data!$K:$K,Data!$A:$A,$A12,Data!$C:$C,T1_Year) -> 61.67 | F12: =SUMIFS(Data!$M:$M,Data!$A:$A,$A12,Data!$C:$C,T1_Year) -> 1133.88 | G12: =SUMIFS(Data!$K:$K,Data!$A:$A,$A12,Data!$C:$C,2013) -> 60.29 | H12: =SUMIFS(Data!$K:$K,Data!$A:$A,$A12,Data!$C:$C,2024) -> 61.67 | I12: =H12-G12 -> 1.38 | J12: =IF($E12>65,"High Risk",IF($E12>=40,"Medium Risk","Low Risk")) -> Medium Risk | K12: =IF($D12,$E12,"") -> 61.67 | L12: =IF($D12,$I12,"") -> 1.38 | M12: =IFERROR(RANK($K12,$K$2:$K$36,0),"") -> 6 | N12: =IF(AND($D12,$B12="East Asia & Pacific"),$F12,"") | O12: =IF(AND($D12,$B12="East Asia & Pacific"),$E12,"") | P12: =IF(AND($D12,$B12="Europe & Central Asia"),$F12,"") | Q12: =IF(AND($D12,$B12="Europe & Central Asia"),$E12,"") | R12: =IF(AND($D12,$B12="Latin America & Caribbean"),$F12,"") | S12: =IF(AND($D12,$B12="Latin America & Caribbean"),$E12,"") | T12: =IF(AND($D12,$B12="Middle East & North Africa"),$F12,"") | U12: =IF(AND($D12,$B12="Middle East & North Africa"),$E12,"") | V12: =IF(AND($D12,$B12="North America"),$F12,"") | W12: =IF(AND($D12,$B12="North America"),$E12,"") | X12: =IF(AND($D12,$B12="South Asia"),$F12,"") | Y12: =IF(AND($D12,$B12="South Asia"),$E12,"") | Z12: =IF(AND($D12,$B12="Sub-Saharan Africa"),$F12,"") -> 1133.88 | AA12: =IF(AND($D12,$B12="Sub-Saharan Africa"),$E12,"") -> 61.67
A13: =CountryMeta!A13 -> France | B13: =CountryMeta!C13 -> Europe & Central Asia | C13: =CountryMeta!D13 -> High income | D13: =AND(OR($B13=T1_Region,T1_Region="All Regions"),OR($C13=T1_Income,T1_Income="All Income Groups")) -> TRUE | E13: =SUMIFS(Data!$K:$K,Data!$A:$A,$A13,Data!$C:$C,T1_Year) -> 29.74 | F13: =SUMIFS(Data!$M:$M,Data!$A:$A,$A13,Data!$C:$C,T1_Year) -> 46103.08 | G13: =SUMIFS(Data!$K:$K,Data!$A:$A,$A13,Data!$C:$C,2013) -> 24.93 | H13: =SUMIFS(Data!$K:$K,Data!$A:$A,$A13,Data!$C:$C,2024) -> 29.74 | I13: =H13-G13 -> 4.81 | J13: =IF($E13>65,"High Risk",IF($E13>=40,"Medium Risk","Low Risk")) -> Low Risk | K13: =IF($D13,$E13,"") -> 29.74 | L13: =IF($D13,$I13,"") -> 4.81 | M13: =IFERROR(RANK($K13,$K$2:$K$36,0),"") -> 28 | N13: =IF(AND($D13,$B13="East Asia & Pacific"),$F13,"") | O13: =IF(AND($D13,$B13="East Asia & Pacific"),$E13,"") | P13: =IF(AND($D13,$B13="Europe & Central Asia"),$F13,"") -> 46103.08 | Q13: =IF(AND($D13,$B13="Europe & Central Asia"),$E13,"") -> 29.74 | R13: =IF(AND($D13,$B13="Latin America & Caribbean"),$F13,"") | S13: =IF(AND($D13,$B13="Latin America & Caribbean"),$E13,"") | T13: =IF(AND($D13,$B13="Middle East & North Africa"),$F13,"") | U13: =IF(AND($D13,$B13="Middle East & North Africa"),$E13,"") | V13: =IF(AND($D13,$B13="North America"),$F13,"") | W13: =IF(AND($D13,$B13="North America"),$E13,"") | X13: =IF(AND($D13,$B13="South Asia"),$F13,"") | Y13: =IF(AND($D13,$B13="South Asia"),$E13,"") | Z13: =IF(AND($D13,$B13="Sub-Saharan Africa"),$F13,"") | AA13: =IF(AND($D13,$B13="Sub-Saharan Africa"),$E13,"")
... A36: =CountryMeta!A36 -> United States | B36: =CountryMeta!C36 -> North America | C36: =CountryMeta!D36 -> High income | D36: =AND(OR($B36=T1_Region,T1_Region="All Regions"),OR($C36=T1_Income,T1_Income="All Income Groups")) -> TRUE | E36: =SUMIFS(Data!$K:$K,Data!$A:$A,$A36,Data!$C:$C,T1_Year) -> 29.04 | F36: =SUMIFS(Data!$M:$M,Data!$A:$A,$A36,Data!$C:$C,T1_Year) -> 86169.66 | G36: =SUMIFS(Data!$K:$K,Data!$A:$A,$A36,Data!$C:$C,2013) -> 24.07 | H36: =SUMIFS(Data!$K:$K,Data!$A:$A,$A36,Data!$C:$C,2024) -> 29.04 | I36: =H36-G36 -> 4.97 | J36: =IF($E36>65,"High Risk",IF($E36>=40,"Medium Risk","Low Risk")) -> Low Risk | K36: =IF($D36,$E36,"") -> 29.04 | L36: =IF($D36,$I36,"") -> 4.97 | M36: =IFERROR(RANK($K36,$K$2:$K$36,0),"") -> 29 | N36: =IF(AND($D36,$B36="East Asia & Pacific"),$F36,"") | O36: =IF(AND($D36,$B36="East Asia & Pacific"),$E36,"") | P36: =IF(AND($D36,$B36="Europe & Central Asia"),$F36,"") | Q36: =IF(AND($D36,$B36="Europe & Central Asia"),$E36,"") | R36: =IF(AND($D36,$B36="Latin America & Caribbean"),$F36,"") | S36: =IF(AND($D36,$B36="Latin America & Caribbean"),$E36,"") | T36: =IF(AND($D36,$B36="Middle East & North Africa"),$F36,"") | U36: =IF(AND($D36,$B36="Middle East & North Africa"),$E36,"") | V36: =IF(AND($D36,$B36="North America"),$F36,"") -> 86169.66 | W36: =IF(AND($D36,$B36="North America"),$E36,"") -> 29.04 | X36: =IF(AND($D36,$B36="South Asia"),$F36,"") | Y36: =IF(AND($D36,$B36="South Asia"),$E36,"") | Z36: =IF(AND($D36,$B36="Sub-Saharan Africa"),$F36,"") | AA36: =IF(AND($D36,$B36="Sub-Saharan Africa"),$E36,"")

Sheet Calc_T2
A1: Country | B1: Region | C1: ScoreEndYear | D1: IncludedScore | E1: RegionRank | G1: SelectedRegion -> | H1: =INDEX($B$2:$B$36,MATCH(T2_Country,$A$2:$A$36,0)) -> South Asia
A2: =CountryMeta!A2 -> Argentina | B2: =CountryMeta!C2 -> Latin America & Caribbean | C2: =SUMIFS(Data!$K:$K,Data!$A:$A,$A2,Data!$C:$C,T2_EndYear) -> 47.99 | D2: =IF($B2=$H$1,$C2,"") | E2: =IFERROR(RANK($D2,$D$2:$D$36,0),"")
A3: =CountryMeta!A3 -> Australia | B3: =CountryMeta!C3 -> East Asia & Pacific | C3: =SUMIFS(Data!$K:$K,Data!$A:$A,$A3,Data!$C:$C,T2_EndYear) -> 17.73 | D3: =IF($B3=$H$1,$C3,"") | E3: =IFERROR(RANK($D3,$D$2:$D$36,0),"")
A4: =CountryMeta!A4 -> Bangladesh | B4: =CountryMeta!C4 -> South Asia | C4: =SUMIFS(Data!$K:$K,Data!$A:$A,$A4,Data!$C:$C,T2_EndYear) -> 63.31 | D4: =IF($B4=$H$1,$C4,"") -> 63.31 | E4: =IFERROR(RANK($D4,$D$2:$D$36,0),"") -> 2
A5: =CountryMeta!A5 -> Brazil | B5: =CountryMeta!C5 -> Latin America & Caribbean | C5: =SUMIFS(Data!$K:$K,Data!$A:$A,$A5,Data!$C:$C,T2_EndYear) -> 50.98 | D5: =IF($B5=$H$1,$C5,"") | E5: =IFERROR(RANK($D5,$D$2:$D$36,0),"")
A6: =CountryMeta!A6 -> Canada | B6: =CountryMeta!C6 -> North America | C6: =SUMIFS(Data!$K:$K,Data!$A:$A,$A6,Data!$C:$C,T2_EndYear) -> 21.14 | D6: =IF($B6=$H$1,$C6,"") | E6: =IFERROR(RANK($D6,$D$2:$D$36,0),"")
A7: =CountryMeta!A7 -> Chile | B7: =CountryMeta!C7 -> Latin America & Caribbean | C7: =SUMIFS(Data!$K:$K,Data!$A:$A,$A7,Data!$C:$C,T2_EndYear) -> 31.44 | D7: =IF($B7=$H$1,$C7,"") | E7: =IFERROR(RANK($D7,$D$2:$D$36,0),"")
A8: =CountryMeta!A8 -> China | B8: =CountryMeta!C8 -> East Asia & Pacific | C8: =SUMIFS(Data!$K:$K,Data!$A:$A,$A8,Data!$C:$C,T2_EndYear) -> 46.59 | D8: =IF($B8=$H$1,$C8,"") | E8: =IFERROR(RANK($D8,$D$2:$D$36,0),"")
A9: =CountryMeta!A9 -> Colombia | B9: =CountryMeta!C9 -> Latin America & Caribbean | C9: =SUMIFS(Data!$K:$K,Data!$A:$A,$A9,Data!$C:$C,T2_EndYear) -> 51.59 | D9: =IF($B9=$H$1,$C9,"") | E9: =IFERROR(RANK($D9,$D$2:$D$36,0),"")
A10: =CountryMeta!A10 -> Congo, Dem. Rep. | B10: =CountryMeta!C10 -> Sub-Saharan Africa | C10: =SUMIFS(Data!$K:$K,Data!$A:$A,$A10,Data!$C:$C,T2_EndYear) -> 72.39 | D10: =IF($B10=$H$1,$C10,"") | E10: =IFERROR(RANK($D10,$D$2:$D$36,0),"")
A11: =CountryMeta!A11 -> Egypt, Arab Rep. | B11: =CountryMeta!C11 -> Middle East & North Africa | C11: =SUMIFS(Data!$K:$K,Data!$A:$A,$A11,Data!$C:$C,T2_EndYear) -> 57.17 | D11: =IF($B11=$H$1,$C11,"") | E11: =IFERROR(RANK($D11,$D$2:$D$36,0),"")
A12: =CountryMeta!A12 -> Ethiopia | B12: =CountryMeta!C12 -> Sub-Saharan Africa | C12: =SUMIFS(Data!$K:$K,Data!$A:$A,$A12,Data!$C:$C,T2_EndYear) -> 61.67 | D12: =IF($B12=$H$1,$C12,"") | E12: =IFERROR(RANK($D12,$D$2:$D$36,0),"")
A13: =CountryMeta!A13 -> France | B13: =CountryMeta!C13 -> Europe & Central Asia | C13: =SUMIFS(Data!$K:$K,Data!$A:$A,$A13,Data!$C:$C,T2_EndYear) -> 29.74 | D13: =IF($B13=$H$1,$C13,"") | E13: =IFERROR(RANK($D13,$D$2:$D$36,0),"")
... A36: =CountryMeta!A36 -> United States | B36: =CountryMeta!C36 -> North America | C36: =SUMIFS(Data!$K:$K,Data!$A:$A,$A36,Data!$C:$C,T2_EndYear) -> 29.04 | D36: =IF($B36=$H$1,$C36,"") | E36: =IFERROR(RANK($D36,$D$2:$D$36,0),"")
